Workbook

Sheet Browse by Category
B1: Browse by Category - generated from 'Asset Index'; use the filter buttons on row 2
B2: id | C2: asset name | D2: category | E2: status | F2: section | G2: priority | H2: price | I2: in Mr Moonlight? | J2: up to date? | K2: purpose in Mr Moonlight | L2: description | M2: notes | N2: collection url | O2: asset store / source | P2: documentation | Q2: downloaded file | R2: publisher | S2: latest version (store) | T2: store updated
B3: AST-041 | C3: Blaze AI Engine | D3: AI & Behavior | E3: Owned | F3: Owned | H3: 40 | I3: Yes | J3: No | K3: MRM-34 Spotter AI and the shared enemy framework (MRM-27 onward). Verified live. | L3: Universal enemy/companion AI: patrol, chase, cover-shooting, hit states on NavMesh. | N3: Collection ↗ | O3: Asset Store ↗ | Q3: Blaze AI Engine v3.4.21 (20 May 2026) | R3: Pathiral | S3: 3.4.22 | T3: 2026-06-22
B4: AST-042 | C4: A* Pathfinding Project Pro | D4: AI & Behavior | E4: Owned | F4: Owned | H4: 140 | I4: No | J4: No | K4: Dropped in Round 2 in favour of Blaze AI (NavMesh). Keep for other projects. | L4: Fast, flexible pathfinding (grid, navmesh, recast) for large worlds. | N4: Collection ↗ | O4: Asset Store ↗ | P4: Docs ↗ | Q4: A Pathfinding Project Pro v5.4.6 | R4: Aron Granberg | S4: 5.4.7 | T4: 2026-08-29
B5: AST-169 | C5: Advanced Zombie AI | D5: AI & Behavior | E5: Owned | F5: Owned (not in project) | G5: Owned (was P2 · #69) | H5: 15 | I5: No | J5: No | K5: Would overlap with Blaze AI — reference only. | L5: Configurable zombie AI system. | M5: [Claude] Merged duplicate (was listed twice). | N5: Collection ↗ | O5: Asset Store ↗ | P5: Docs ↗ | Q5: Advanced Zombie AI v1.0.3 | R5: Finite Machine Studio | S5: 1.0.4 | T5: 2026-07-30
B6: AST-264 | C6: SensorToolkit 2 | D6: AI & Behavior | E6: Owned | F6: Owned (not in project) | G6: Owned (new · not on original list) | H6: 45 | I6: No | J6: Yes | K6: Not assigned yet. Candidate for enemy senses (vision / proximity) - overlaps Blaze AI's built-in detection, so evaluate before adopting. | L6: Sensor components (raycast, range, field-of-view, trigger) that detect and report nearby objects. | M6: [Claude] Added 2026-09-19 — acquired outside the original list; not installed in any project yet. | N6: Collection ↗ | O6: Asset Store ↗ | Q6: SensorToolkit 2 v2.5.19 | R6: Micosmo | S6: 2.5.19 | T6: 2026-09-12
B7: AST-265 | C7: Emerald AI 2026 | D7: AI & Behavior | E7: Owned | F7: Owned (not in project) | G7: Owned (new · not on original list) | H7: 60 | I7: No | J7: Yes | K7: Not assigned yet. Alternative enemy AI framework - Mr. Moonlight's enemies run on Blaze AI, so reference/comparison only unless that changes. | L7: Universal AI framework, rewritten: modular components, easy editors, many built-in features. | M7: [Claude] Added 2026-09-19 — acquired outside the original list; not installed in any project yet. | N7: Collection ↗ | O7: Asset Store ↗ | Q7: Emerald AI 2026 v1.3.4 | R7: Black Horizon Studios | S7: 1.3.4 | T7: 2026-09-14
B8: AST-300 | C8: Mobile Traffic System v3 | D8: AI & Behavior | E8: Owned | F8: Owned (not in project) | G8: Owned (new · not on original list) | H8: 129 | I8: No | J8: No | K8: Not assigned yet. Other projects (driving). | L8: Traffic system for vehicle AI and city traffic (store page has no description; summary from title and tags). | M8: [Claude] Added 2026-10-08 — acquired outside the original list. File v3.6.1 is behind the store (3.6.5). Not installed anywhere. | N8: Collection ↗ | O8: Asset Store ↗ | Q8: Mobile Traffic System v3 v3.6.1 | R8: Gley | S8: 3.6.5 | T8: 2026-09-29
B9: AST-101 | C9: Blaze AI Engine - Hearing | D9: AI & Behavior | E9: Wishlist | F9: Wishlist P1 | G9: P1 · #1 | H9: 7.99 | I9: No | J9: — | K9: Enemies react to gunshots and footsteps — direct upgrade to the Spotter/enemy framework. | L9: Blaze AI module: agents hear sounds on chosen layers. | M9: Can be used for hearing detection on the Blaze engine. | O9: Asset Store ↗ | R9: Pathiral | S9: 1.0.1 | T9: 2025-07-04
B10: AST-102 | C10: Blaze AI Engine - Predator | D10: AI & Behavior | E10: Wishlist | F10: Wishlist P1 | G10: P1 · #2 | H10: 15 | I10: No | J10: — | K10: Stalking behaviour for the Wendigo, the wolf and feral enemies. | L10: Blaze AI module: predator behaviour that stalks and hunts prey. | M10: Can be used to extend the Blaze behaviors for the enemies | O10: Asset Store ↗ | R10: Pathiral | S10: 1.3.0 | T10: 2025-05-10
B11: AST-013 | C11: Retarget Pro V5 | D11: Animation & Rigging Tools | E11: Owned | F11: Owned | H11: 59.99 | I11: No | J11: Yes | K11: Deliberately Playground-only: bakes clips for the Wendigo, wolf and Tracey's body (MRM-75 / MRM-36). Only the baked clips migrate, the tool never does. | L11: Animation retargeting between any rigs (Humanoid or not) with bake-to-clip output (KINEMATION). | N11: Collection ↗ | O11: Asset Store ↗ | P11: Docs ↗ | Q11: Retarget Pro V5 v5.2.1 | R11: KINEMATION | S11: 5.2.1 | T11: 2026-08-26
B12: AST-082 | C12: DOTween Pro | D12: Animation & Rigging Tools | E12: Owned | F12: Owned (added later) | H12: 15 | I12: Yes | J12: Unknown | K12: Project standard for smooth transitions (menu title reveal, UI fades). | L12: Tweening engine: move, fade, shake, paths and sequences, with visual editors. | M12: [Claude] Added — found in the project / project docs, was not on the list. | O12: Asset Store ↗ | P12: Docs ↗ | Q12: Installed — version not recorded | R12: Demigiant | S12: 1.0.430 | T12: 2026-06-23
B13: AST-103 | C13: Feel | D13: Animation & Rigging Tools | E13: Owned | F13: Owned (not in project) | G13: Owned (was P1 · #3) | H13: 50 | I13: No | J13: No | K13: Recoil, hit feedback, fear shakes and UI juice across many systems. | L13: Game-feel toolkit: screen shake, hit-stop, flashes, bounces, 150+ feedbacks. | M13: Very nice effects that bring life into animations and projects and whatever | N13: Collection ↗ | O13: Asset Store ↗ | P13: Docs ↗ | Q13: Feel v6.0 | R13: More Mountains | S13: 6.1 | T13: 2026-08-31
B14: AST-120 | C14: Final IK | D14: Animation & Rigging Tools | E14: Owned | F14: Owned (not in project) | G14: Owned (was P1 · #20) | H14: 90 | I14: No | J14: Yes | K14: Enemy aiming/look-at, foot grounding on sloped terrain, and Tracey's look-down body. | L14: Complete inverse-kinematics suite: aim, look-at, full-body biped, grounding. | M14: Could be useful for improving animations | N14: Collection ↗ | O14: Asset Store ↗ | Q14: Final IK v2.5 (11 Apr 2026) | R14: RootMotion | S14: 2.5 | T14: 2026-04-10
B15: AST-156 | C15: Mesh Transformation | D15: Animation & Rigging Tools | E15: Owned | F15: Owned (not in project) | G15: Owned (was P2 · #56) | H15: 14.45 | I15: No | J15: Yes | K15: The werewolf transformation. | L15: Mesh-to-mesh transformation animations (werewolf, mutant, healing). | M15: Could be useful for transformation. For example the werewolf enemy | N15: Collection ↗ | O15: Asset Store ↗ | Q15: Mesh Transformation v1.9 | R15: Andrey Graphics | S15: 1.9 | T15: 2020-09-02
B16: AST-172 | C16: Character Animation System | D16: Animation & Rigging Tools | E16: Owned | F16: Owned (not in project) | G16: Owned (was P3 · #72) | H16: 79.99 | I16: No | J16: No | K16: Later: procedural polish for Tracey's body. Mostly for future projects. | L16: Modular procedural animation layer: blending, IK, additive layers (KINEMATION). | N16: Collection ↗ | O16: Asset Store ↗ | P16: Docs ↗ | Q16: Character Animation System v2.1.2 | R16: KINEMATION | S16: 2.4.1 | T16: 2026-08-17
B17: AST-183 | C17: BoneToPix - 3D & Bone Animation To Pixel-Art Converter | D17: Animation & Rigging Tools | E17: Owned | F17: Owned (not in project) | G17: Owned (was P3 · #83) | H17: 24.99 | I17: No | J17: No | K17: Other projects (2D pixel art). | L17: Converts 3D models/animations into pixel-art sprites with lighting. | N17: Collection ↗ | O17: Asset Store ↗ | Q17: BoneToPix - 3D Bone Animation To Pixel-Art Converter v2.9.1 | R17: GeorgeBGreen | S17: 2.9.2 | T17: 2025-08-07
B18: AST-197 | C18: Animation to Sprite Sheet – Export animations into 2D sprite sheets easily | D18: Animation & Rigging Tools | E18: Owned | F18: Owned (not in project) | G18: Owned (was P3 · #97) | H18: 15 | I18: No | J18: Yes | K18: Other projects (2D). | L18: Exports 3D animations to 2D sprite sheets. | N18: Collection ↗ | O18: Asset Store ↗ | Q18: Animation to Sprite Sheet - Export animations into 2D sprite sheets easily v1.0 | R18: Zuppy | S18: 1.0 | T18: 2025-10-28
B19: AST-290 | C19: Tail Animator | D19: Animation & Rigging Tools | E19: Owned | F19: Owned (not in project) | G19: Owned (new · not on original list) | H19: 25.99 | I19: No | J19: Yes | K19: Not assigned yet. Procedural secondary motion (tails, hair, cloth-like parts) on creatures. | L19: Procedural tail / tentacle / secondary-motion animation tool. | M19: [Claude] Added 2026-10-05 — acquired outside the original list. | N19: Collection ↗ | O19: Asset Store ↗ | Q19: Tail Animator v2.5.3 (21 Sep 2026) | R19: FImpossible Creations | S19: 2.5.3 | T19: 2026-09-21
B20: AST-291 | C20: Legs Animator | D20: Animation & Rigging Tools | E20: Owned | F20: Owned (not in project) | G20: Owned (new · not on original list) | H20: 43.99 | I20: No | J20: Yes | K20: Not assigned yet. Procedural leg placement on uneven ground for creatures/enemies. | L20: Procedural leg placement and walking animation for humanoids and animals (spiders, insects). | M20: [Claude] Added 2026-10-05 — acquired outside the original list. | N20: Collection ↗ | O20: Asset Store ↗ | Q20: Legs Animator v1.0.4.6 (21 Sep 2026) | R20: FImpossible Creations | S20: 1.0.4.6 | T20: 2026-09-21
B21: AST-299 | C21: Animation Designer | D21: Animation & Rigging Tools | E21: Owned | F21: Owned (not in project) | G21: Owned (new · not on original list) | H21: 59.99 | I21: No | J21: Yes | K21: Not assigned yet. Animation tooling candidate. | L21: Animation authoring toolkit for procedural and humanoid animation, with IK support (store page has no description; summary from title and tags). | M21: [Claude] Added 2026-10-08 — acquired outside the original list. Not installed anywhere. | N21: Collection ↗ | O21: Asset Store ↗ | Q21: Animation Designer v1.3.1 (21 Sep 2026) | R21: FImpossible Creations | S21: 1.3.1 | T21: 2026-09-21
B22: AST-306 | C22: Jiggling | D22: Animation & Rigging Tools | E22: Owned | F22: Owned (not in project) | G22: Owned (new · not on original list) | H22: 4.99 | I22: No | J22: Yes | K22: Not assigned yet. Carlos's idea (2026-10-11): shake and wobble for the earthquake event. | L22: Jiggle animation by rotation and scaling only, two-click setup: hit impulses, scale pulses, source included. | M22: [Claude] Added 2026-10-11 — acquired outside the original list. | N22: Collection ↗ | O22: Asset Store ↗ | Q22: Jiggling v1.1.5 | R22: FImpossible Creations | S22: 1.1.5 | T22: 2026-10-07
B23: AST-311 | C23: AnimFuse - Animation Blending, Pose Editing and Baking | D23: Animation & Rigging Tools | E23: Owned | F23: Owned (not in project) | G23: Owned (new · not on original list) | H23: 19.99 | I23: No | J23: No | K23: Not assigned yet. Animation tooling for later or other projects. | L23: Animation blending, pose editing and baking, including upper-body and aiming setups for humanoids. | M23: [Claude] Added 2026-10-27 — acquired outside the original list. | N23: Collection ↗ | O23: Asset Store ↗ | Q23: AnimFuse Animation Blending Pose Editing and Baking v1.0 | R23: Finite Machine Studio | S23: 1.0.4 | T23: 2026-10-22
B24: AST-313 | C24: Realistic Eye Movements | D24: Animation & Rigging Tools | E24: Owned | F24: Owned (not in project) | G24: Owned (new · not on original list) | H24: 25 | I24: No | J24: Yes | K24: Not assigned yet. Eyes for enemies and characters; later or other projects. | L24: Realistic eye movement, gaze and blinking for characters. | M24: [Claude] Added 2026-10-27 — acquired outside the original list. | N24: Collection ↗ | O24: Asset Store ↗ | Q24: Realistic Eye Movements v2.1.14 | R24: Tore Knabe | S24: 2.1.14 | T24: 2026-03-16
B25: AST-019 | C25: Cult Animations | D25: Animation — Clips & Mocap | E25: Owned | F25: Owned | H25: 8 | I25: No | J25: Yes | K25: Adopted for MRM-59 cult staging scenes. | L25: 25 motion-captured cult / ritual animations. | N25: Collection ↗ | O25: Asset Store ↗ | Q25: Cult Animations v1.0 | R25: Gem Gaming Animations | S25: 1.0 | T25: 2024-05-31
B26: AST-022 | C26: ANIMSET: 2 HANDED MELEE WEAPON | D26: Animation — Clips & Mocap | E26: Owned | F26: Owned | H26: 19.99 | I26: No | J26: No | K26: Adopted for MRM-23 melee. Also included inside Ultimate Animation Collection. | L26: Mocap animation set for two-handed melee weapons. | N26: Collection ↗ | O26: Asset Store ↗ | Q26: ANIMSET 2 HANDED MELEE WEAPON v1.5 | R26: PROTOFACTOR, INC | S26: 1.642 | T26: 2026-07-06
B27: AST-026 | C27: Knife_MocapAnimPack_1.1 | D27: Animation — Clips & Mocap | E27: Owned | F27: Owned | H27: 45 | I27: No | J27: Yes | K27: Adopted for MRM-35 knife-wielding enemy. | L27: Mocap knife combat animation pack. | N27: Collection ↗ | O27: Asset Store ↗ | Q27: Knife_MocapAnimPack v1.1 (21 Aug 2026) | R27: RIB Studio | S27: 1.1 | T27: 2026-08-24
B28: AST-044 | C28: ULTIMATE ANIMATION COLLECTION | D28: Animation — Clips & Mocap | E28: Owned | F28: Owned | H28: 259.99 | I28: Yes | J28: Yes | K28: Installed — enemy locomotion/combat clips (MRM-31 / 29 / 35 / 37). ⚠ Import selectively. | L28: Huge human mocap library for Mecanim Humanoid (3,000+ clips). | N28: Collection ↗ | O28: Asset Store ↗ | Q28: ULTIMATE ANIMATION COLLECTION v1.65 | R28: PROTOFACTOR, INC | S28: 1.65 | T28: 2026-08-16
B29: AST-061 | C29: Human Mega Animations Pack | D29: Animation — Clips & Mocap | E29: Owned | F29: Owned | H29: 130 | I29: No | J29: Yes | K29: Extra humanoid clips for NPCs and enemies. | L29: All of Kevin Iglesias' human animations in one pack. | M29: A lot of useful animations | N29: Collection ↗ | O29: Asset Store ↗ | Q29: Human Mega Animations Pack v2.0 (06 May 2026) | R29: Kevin Iglesias | S29: 2.0 | T29: 2026-05-06
B30: AST-069 | C30: Stealth Finishers - Knife and Hand | D30: Animation — Clips & Mocap | E30: Owned | F30: Owned | H30: 39.99 | I30: No | J30: Yes | K30: Melee enemy attacks and takedowns. | L30: Knife/hand stealth finishers, cover movement and body carry/drag. | M30: Contains some animations that can be used for melee enemies. | N30: Collection ↗ | O30: Asset Store ↗ | Q30: Stealth Finishers - Knife and Hand v1.0 | R30: RamsterZ | S30: 1.0 | T30: 2022-07-04
B31: AST-121 | C31: Zombie Animations Set | D31: Animation — Clips & Mocap | E31: Owned | F31: Owned (not in project) | G31: Owned (was P1 · #21) | H31: 24.99 | I31: No | J31: No | K31: Zombie/feral enemies. | L31: Zombie animations: paired grabs, crawls, hit reactions, deaths. | M31: Can be useful for the zombies | N31: Collection ↗ | O31: Asset Store ↗ | Q31: Zombie Animations Set v1.0 | R31: RamsterZ | S31: 1.3.0 | T31: 2026-07-19
B32: AST-122 | C32: Ghost Creature Anims | D32: Animation — Clips & Mocap | E32: Owned | F32: Owned (not in project) | G32: Owned (was P1 · #22) | H32: 29.99 | I32: No | J32: Yes | K32: Enemy animations. | L32: 89 ghost and horror-victim animations with paired attacks. | M32: Useful animations for the enemies | N32: Collection ↗ | O32: Asset Store ↗ | Q32: Ghost Creature Anims v1.2 | R32: RamsterZ | S32: 1.2 | T32: 2022-07-04
B33: AST-123 | C33: Witch Hag Animations | D33: Animation — Clips & Mocap | E33: Owned | F33: Owned (not in project) | G33: Owned (was P1 · #23) | H33: 29.99 | I33: No | J33: Yes | K33: Enemy animations. | L33: Stooped witch/hag horror animations. | M33: Have useful animations for the enemies. | N33: Collection ↗ | O33: Asset Store ↗ | Q33: Witch Hag Animations v1.0 | R33: RamsterZ | S33: 1.0 | T33: 2023-09-27
B34: AST-124 | C34: Killer Doll Animations | D34: Animation — Clips & Mocap | E34: Owned | F34: Owned (not in project) | G34: Owned (was P1 · #24) | H34: 24.99 | I34: No | J34: Yes | K34: Enemy animations. | L34: Twitchy, unnatural doll/monster animations (+ bonus model). | M34: Useful animations for the enemies | N34: Collection ↗ | O34: Asset Store ↗ | Q34: Killer Doll Animations v1.0.1 | R34: RamsterZ | S34: 1.0.1 | T34: 2026-02-18
B35: AST-132 | C35: Dialogue Anims | D35: Animation — Clips & Mocap | E35: Owned | F35: Owned (not in project) | G35: Owned (was P1 · #32) | H35: 15 | I35: No | J35: Yes | K35: The Legion mode merchant. | L35: 104 dialogue/talking animations in many styles. | M35: Could be useful for the merchant. This is for the Legion mode on the store. | N35: Collection ↗ | O35: Asset Store ↗ | Q35: Dialogue Anims v1.0 | R35: RamsterZ | S35: 1.0 | T35: 2022-05-20
B36: AST-133 | C36: Classic Female Ghost | D36: Animation — Clips & Mocap | E36: Owned | F36: Owned (not in project) | G36: Owned (was P1 · #33) | H36: 29.99 | I36: No | J36: Yes | K36: Enemy animations. | L36: Ethereal female ghost/witch horror animations. | M36: Useful animations for the enemies Could have useful animations for the enemies [Claude] Merged duplicate (was listed twice). | N36: Collection ↗ | O36: Asset Store ↗ | Q36: Classic Female Ghost v1.0 | R36: RamsterZ | S36: 1.0 | T36: 2023-10-05
B37: AST-134 | C37: Demon Anims | D37: Animation — Clips & Mocap | E37: Owned | F37: Owned (not in project) | G37: Owned (was P1 · #34) | H37: 24.99 | I37: No | J37: Yes | K37: Enemy animations. | L37: Demon/ghost animations with jump scares and victim clips. | M37: Could have some useful animations | N37: Collection ↗ | O37: Asset Store ↗ | Q37: Demon Anims v1.0 | R37: RamsterZ | S37: 1.0 | T37: 2022-06-21
B38: AST-135 | C38: Asylum NPC Animations | D38: Animation — Clips & Mocap | E38: Owned | F38: Owned (not in project) | G38: Owned (was P1 · #35) | H38: 15.99 | I38: No | J38: Yes | K38: Enemy/NPC animations. | L38: Asylum patient/inmate animations. | M38: Could have useful animations for the enemies | N38: Collection ↗ | O38: Asset Store ↗ | Q38: Asylum NPC Animations v1.0 | R38: RamsterZ | S38: 1.0 | T38: 2024-09-10
B39: AST-137 | C39: Female Clown | D39: Animation — Clips & Mocap | E39: Owned | F39: Owned (not in project) | G39: Owned (was P1 · #37) | H39: 19.99 | I39: No | J39: Yes | K39: Daddy's Joke or similar stage enemies. | L39: Bat-wielding thug/clown combat animations and emotes. | M39: Useful animation, probably for daddy's joke or stage tail enemies. | N39: Collection ↗ | O39: Asset Store ↗ | Q39: Female Clown v1.0 | R39: RamsterZ | S39: 1.0 | T39: 2024-09-26
B40: AST-139 | C40: Goblin Anims | D40: Animation — Clips & Mocap | E40: Owned | F40: Owned (not in project) | G40: Owned (was P1 · #39) | H40: 24.99 | I40: No | J40: Yes | K40: A smaller Legion enemy. | L40: Goblin/small biped animations: combat, ambushes, movement. | M40: Could be useful for a smaller type of enemy in Legion, probably the Batman, which I haven't described yet. | N40: Collection ↗ | O40: Asset Store ↗ | Q40: Goblin Anims v1.0 | R40: RamsterZ | S40: 1.0 | T40: 2023-06-12
...

Sheet By Category
B2: category | C2: owned | D2: wishlist | E2: total | F2: in Mr Moonlight (Yes)
B3: AI & Behavior | C3: =COUNTIFS('Browse by Category'!$D$3:$D$317,$B3,'Browse by Category'!$E$3:$E$317,"Owned") | D3: =COUNTIFS('Browse by Category'!$D$3:$D$317,$B3,'Browse by Category'!$E$3:$E$317,"Wishlist") | E3: =C3+D3 | F3: =COUNTIFS('Browse by Category'!$D$3:$D$317,$B3,'Browse by Category'!$I$3:$I$317,"Yes*")
B4: Animation & Rigging Tools | C4: =COUNTIFS('Browse by Category'!$D$3:$D$317,$B4,'Browse by Category'!$E$3:$E$317,"Owned") | D4: =COUNTIFS('Browse by Category'!$D$3:$D$317,$B4,'Browse by Category'!$E$3:$E$317,"Wishlist") | E4: =C4+D4 | F4: =COUNTIFS('Browse by Category'!$D$3:$D$317,$B4,'Browse by Category'!$I$3:$I$317,"Yes*")
B5: Animation — Clips & Mocap | C5: =COUNTIFS('Browse by Category'!$D$3:$D$317,$B5,'Browse by Category'!$E$3:$E$317,"Owned") | D5: =COUNTIFS('Browse by Category'!$D$3:$D$317,$B5,'Browse by Category'!$E$3:$E$317,"Wishlist") | E5: =C5+D5 | F5: =COUNTIFS('Browse by Category'!$D$3:$D$317,$B5,'Browse by Category'!$I$3:$I$317,"Yes*")
B6: Audio Tools | C6: =COUNTIFS('Browse by Category'!$D$3:$D$317,$B6,'Browse by Category'!$E$3:$E$317,"Owned") | D6: =COUNTIFS('Browse by Category'!$D$3:$D$317,$B6,'Browse by Category'!$E$3:$E$317,"Wishlist") | E6: =C6+D6 | F6: =COUNTIFS('Browse by Category'!$D$3:$D$317,$B6,'Browse by Category'!$I$3:$I$317,"Yes*")
B7: Audio — Music | C7: =COUNTIFS('Browse by Category'!$D$3:$D$317,$B7,'Browse by Category'!$E$3:$E$317,"Owned") | D7: =COUNTIFS('Browse by Category'!$D$3:$D$317,$B7,'Browse by Category'!$E$3:$E$317,"Wishlist") | E7: =C7+D7 | F7: =COUNTIFS('Browse by Category'!$D$3:$D$317,$B7,'Browse by Category'!$I$3:$I$317,"Yes*")
B8: Audio — SFX & Ambience | C8: =COUNTIFS('Browse by Category'!$D$3:$D$317,$B8,'Browse by Category'!$E$3:$E$317,"Owned") | D8: =COUNTIFS('Browse by Category'!$D$3:$D$317,$B8,'Browse by Category'!$E$3:$E$317,"Wishlist") | E8: =C8+D8 | F8: =COUNTIFS('Browse by Category'!$D$3:$D$317,$B8,'Browse by Category'!$I$3:$I$317,"Yes*")
B9: Blender Add-ons | C9: =COUNTIFS('Browse by Category'!$D$3:$D$317,$B9,'Browse by Category'!$E$3:$E$317,"Owned") | D9: =COUNTIFS('Browse by Category'!$D$3:$D$317,$B9,'Browse by Category'!$E$3:$E$317,"Wishlist") | E9: =C9+D9 | F9: =COUNTIFS('Browse by Category'!$D$3:$D$317,$B9,'Browse by Category'!$I$3:$I$317,"Yes*")
B10: Characters — Animals | C10: =COUNTIFS('Browse by Category'!$D$3:$D$317,$B10,'Browse by Category'!$E$3:$E$317,"Owned") | D10: =COUNTIFS('Browse by Category'!$D$3:$D$317,$B10,'Browse by Category'!$E$3:$E$317,"Wishlist") | E10: =C10+D10 | F10: =COUNTIFS('Browse by Category'!$D$3:$D$317,$B10,'Browse by Category'!$I$3:$I$317,"Yes*")
B11: Characters — Anime | C11: =COUNTIFS('Browse by Category'!$D$3:$D$317,$B11,'Browse by Category'!$E$3:$E$317,"Owned") | D11: =COUNTIFS('Browse by Category'!$D$3:$D$317,$B11,'Browse by Category'!$E$3:$E$317,"Wishlist") | E11: =C11+D11 | F11: =COUNTIFS('Browse by Category'!$D$3:$D$317,$B11,'Browse by Category'!$I$3:$I$317,"Yes*")
B12: Characters — Gooner | C12: =COUNTIFS('Browse by Category'!$D$3:$D$317,$B12,'Browse by Category'!$E$3:$E$317,"Owned") | D12: =COUNTIFS('Browse by Category'!$D$3:$D$317,$B12,'Browse by Category'!$E$3:$E$317,"Wishlist") | E12: =C12+D12 | F12: =COUNTIFS('Browse by Category'!$D$3:$D$317,$B12,'Browse by Category'!$I$3:$I$317,"Yes*")
B13: Characters — Horror & Creatures | C13: =COUNTIFS('Browse by Category'!$D$3:$D$317,$B13,'Browse by Category'!$E$3:$E$317,"Owned") | D13: =COUNTIFS('Browse by Category'!$D$3:$D$317,$B13,'Browse by Category'!$E$3:$E$317,"Wishlist") | E13: =C13+D13 | F13: =COUNTIFS('Browse by Category'!$D$3:$D$317,$B13,'Browse by Category'!$I$3:$I$317,"Yes*")
B14: Characters — Humans & Stylized | C14: =COUNTIFS('Browse by Category'!$D$3:$D$317,$B14,'Browse by Category'!$E$3:$E$317,"Owned") | D14: =COUNTIFS('Browse by Category'!$D$3:$D$317,$B14,'Browse by Category'!$E$3:$E$317,"Wishlist") | E14: =C14+D14 | F14: =COUNTIFS('Browse by Category'!$D$3:$D$317,$B14,'Browse by Category'!$I$3:$I$317,"Yes*")
... B34: Water | C34: =COUNTIFS('Browse by Category'!$D$3:$D$317,$B34,'Browse by Category'!$E$3:$E$317,"Owned") | D34: =COUNTIFS('Browse by Category'!$D$3:$D$317,$B34,'Browse by Category'!$E$3:$E$317,"Wishlist") | E34: =C34+D34 | F34: =COUNTIFS('Browse by Category'!$D$3:$D$317,$B34,'Browse by Category'!$I$3:$I$317,"Yes*")
B35: TOTAL | C35: =SUM(C3:C34) | D35: =SUM(D3:D34) | E35: =SUM(E3:E34) | F35: =SUM(F3:F34)

Sheet Asset Index
B1: Asset Index | E1: Updated 2026-10-27 · prices are full (non-sale) store prices in USD · see the Legend sheet
B2: id | C2: asset name | D2: category | E2: description | F2: collection url | G2: asset store / source | H2: price | I2: in Mr Moonlight? | J2: purpose in Mr Moonlight | K2: notes | L2: documentation | M2: downloaded file | N2: up to date? | O2: status | P2: priority | Q2: publisher | R2: latest version (store) | S2: store updated
B3: OWNED — downloaded assets
B4: AST-001 | C4: Gore Simulator | D4: VFX — Blood & Gore | E4: Runtime dismemberment, cuts and gore meshes for any skinned character. | F4: Collection ↗ | G4: Asset Store ↗ | H4: 65.95 | I4: Yes | J4: MRM-32 / MRM-36 / MRM-37 — limb cutting on enemies. The Spotter already uses it (GoreStorage_Spotter). Vendor code lives in _Project/Code/Vendor/Gore Simulator. | L4: Docs ↗ | M4: Gore Simulator v1.8.8 | N4: Yes | O4: Owned | Q4: Pampel Games | R4: 1.8.8 | S4: 2026-06-28
B5: AST-002 | C5: InfiniCLOUD HDRP - URP, Volumetric clouds & particles | D5: Sky & Atmosphere | E5: Performance-focused volumetric cloud meshes and cloud particles for URP/HDRP. | F5: Collection ↗ | G5: Asset Store ↗ | H5: 49 | I5: Yes | J5: Installed (InfiniCloud URP – single-mesh clouds): cloud layer in the island sky. | M5: InfiniCLOUD HDRP - URP Volumetric clouds particles v2.0.4 (22 Dec 2025) | N5: No | O5: Owned | Q5: ARTnGAME | R5: 2.0.5 | S5: 2026-06-23
B6: AST-003 | C6: Dynamic Radial Masks | D6: Shaders & Post-Processing | E6: Shader extension that projects animated world-space radial masks (ripples, reveals, dissolves) onto any material. | F6: Collection ↗ | G6: Asset Store ↗ | H6: 35 | I6: Yes | J6: MRM-18 — drives the ported rain-ripple effect on water/ground. Vendor code in _Project/Code/Vendor. ⚠ Ripple count is baked into the shader (only 8/64/200 work). | L6: Docs ↗ | M6: Dynamic Radial Masks v2025.3 (18 Dec 2025) | N6: No | O6: Owned | Q6: Amazing Аssets | R6: 2026.5 | S6: 2026-09-05
B7: AST-004 | C7: Cartoon Rain & Blood Rain | D7: VFX — Particles | E7: Rain particle systems (drops, ripples, splashes) including a blood-rain variant; Wind Zone aware. | F7: Collection ↗ | G7: Asset Store ↗ | H7: 6.99 | I7: Yes | J7: Rain particles for the island and main-menu staging (MRM-18). The blood-rain variant is a candidate for Legion mode. | M7: Cartoon Rain Blood Rain v1.1 | N7: Yes | O7: Owned | Q7: BG Studio | R7: 1.1 | S7: 2022-07-25
B8: AST-005 | C8: Shiny SSR 2 - Screen Space Reflections | D8: Shaders & Post-Processing | E8: Screen-space reflections post effect with quality/performance controls (Kronnect). | F8: Collection ↗ | G8: Asset Store ↗ | H8: 51.99 | I8: No | J8: Tried for water reflections in MRM-18, then removed — Crest planar reflections replaced it. | L8: Docs ↗ | M8: Shiny SSR 2 - Screen Space Reflections v32.3.1 | N8: No | O8: Owned | Q8: Kronnect | R8: 32.4.1 | S8: 2026-08-24
B9: AST-006 | C9: PIDI - Planar Reflections 6: URP Edition. | D9: Shaders & Post-Processing | E9: Real-time planar reflections for flat surfaces (mirrors, floors, water). | F9: Collection ↗ | G9: Asset Store ↗ | H9: 40 | I9: No | J9: Evaluated only. Crest handles water reflections now; could still serve mirrors/wet floors in interiors. | K9: [Claude] You own v5 Personal; the store link is PIDI 6 URP, a separate new product (not a free update). | L9: Docs ↗ | M9: PIDI Planar Reflections 5 - Personal Edition v5.4.1 | N9: No | O9: Owned | Q9: Irreverent Software - PIDI | R9: 6.2.8 | S9: 2026-08-07
B10: AST-007 | C10: URP Mirror Shaders / AR-VR Ready | D10: Shaders & Post-Processing | E10: Mirror/reflection shaders for URP including AR/VR support (AkilliMum). | F10: Collection ↗ | G10: Asset Store ↗ | H10: 25 | I10: No | J10: Playground evaluation only. Possible use: mirrors in the cabin or church interiors. | L10: Docs ↗ | M10: URP Mirror Shaders AR-VR Ready v5.11 | N10: No | O10: Owned | Q10: Akıllı Mum | R10: 5.13 | S10: 2025-02-03
B11: AST-008 | C11: Guns Sounds - Sound Effects | D11: Audio — SFX & Ambience | E11: Small pack of firearm shot / reload sound effects. | F11: Collection ↗ | G11: Asset Store ↗ | H11: 4.99 | I11: No | J11: Playground only. Extra weapon SFX layers for MRM-22 / MRM-24 if HQ FPS Weapons' audio falls short. | M11: Guns Sounds - Sound Effects v1.0 | N11: Yes | O11: Owned | Q11: AD Sounds | R11: 1.0 | S11: 2025-06-22
B12: AST-009 | C12: Damage Numbers Pro | D12: UI & HUD | E12: Spawns animated number/text popups (damage, crits, pickups) with 2–3 lines of code. | F12: Collection ↗ | G12: Asset Store ↗ | H12: 7.99 | I12: Yes | J12: Installed with vendor code — floating hit/damage numbers. | M12: Damage Numbers Pro v4.56 | N12: Yes | O12: Owned | Q12: Ekincan Tas | R12: 4.56 | S12: 2026-08-29
B13: AST-010 | C13: Outdoor Atmospheres Sound Effects Pack | D13: Audio — SFX & Ambience | E13: 60+ outdoor soundscapes: forests, tundra, mountains, swamp, snow and fantasy lands. | F13: Collection ↗ | G13: Asset Store ↗ | H13: 25 | I13: No | J13: Adopted for MRM-38 sound layers (forest/tundra beds). Import compressed, never WAV. | L13: Docs ↗ | M13: Outdoor Atmospheres Sound Effects Pack v2.0 | N13: Yes | O13: Owned | Q13: Olivier Girardot | R13: 2.0 | S13: 2020-12-29
B14: AST-011 | C14: Industrial Shipping Container Pack | D14: Props & Weapons | E14: High-quality industrial cargo/shipping containers. | F14: Collection ↗ | G14: Asset Store ↗ | H14: 19.99 | I14: No | J14: Adopted for MRM-60 staging (docks, mine infirmary). | M14: Industrial Shipping Container Pack v1.0 | N14: Yes | O14: Owned | Q14: EVOLVE Studio LTD | R14: 1.0 | S14: 2024-08-05
B15: AST-012 | C15: Controller Overlays & Button Kits (3 styles) x9 controllers +keyboard/mouse | D15: UI & HUD | E15: Controller/keyboard button icon kits for 9 popular gamepads, 3 styles. | F15: Collection ↗ | G15: Asset Store ↗ | H15: 19.99 | I15: No | J15: Playground only. Button prompts for gamepad UI (menus, interaction hints). | M15: Controller Overlays Button Kits (3 styles) x8 controllers keyboard mouse v1.9.2 | N15: No | O15: Owned | Q15: nickknacks | R15: 1.9.3 | S15: 2025-08-04
B16: AST-013 | C16: Retarget Pro V5 | D16: Animation & Rigging Tools | E16: Animation retargeting between any rigs (Humanoid or not) with bake-to-clip output (KINEMATION). | F16: Collection ↗ | G16: Asset Store ↗ | H16: 59.99 | I16: No | J16: Deliberately Playground-only: bakes clips for the Wendigo, wolf and Tracey's body (MRM-75 / MRM-36). Only the baked clips migrate, the tool never does. | L16: Docs ↗ | M16: Retarget Pro V5 v5.2.1 | N16: Yes | O16: Owned | Q16: KINEMATION | R16: 5.2.1 | S16: 2026-08-26
B17: AST-014 | C17: Aged Medieval PBR Tools | D17: Props & Weapons | E17: 7 aged PBR farm/medieval tools (shovel, axe, rake, hammer, sickle…). | F17: Collection ↗ | G17: Asset Store ↗ | H17: 4.99 | I17: No | J17: Adopted for MRM-35 — the sickle only. | M17: Aged Medieval PBR Tools v1.01 | N17: Yes | O17: Owned | Q17: BasicCore | R17: 1.01 | S17: 2016-09-26
B18: AST-015 | C18: Ian's Fire Pack | D18: VFX — Particles | E18: 29 drag-and-drop fire prefabs, from candles to burning trees, with sounds. | F18: Collection ↗ | G18: Asset Store ↗ | H18: 30 | I18: Yes | J18: Installed — fire/flame effects (flare, campfires, burning props; MRM-61). | M18: Ians Fire Pack v2.3 | N18: Yes | O18: Owned | Q18: Ian Scilipoti | R18: 2.3 | S18: 2021-04-13
B19: AST-016 | C19: HE - Abandoned Hospital v.2 | D19: Environments & Level Kits | E19: Large modular abandoned-hospital interior kit (URP/HDRP). | F19: Collection ↗ | G19: Asset Store ↗ | H19: 19 | I19: No | J19: Adopted for MRM-60 — the infirmary inside the mine. | K19: [Claude] Store version is now v2.0; you have v1.4. | M19: HE - Abandoned Hospital v1.4 | N19: No | O19: Owned | Q19: Artur G. | R19: 2.0 | S19: 2025-02-07
B20: AST-017 | C20: Realistic Gun VFX (Muzzle Flash, Bullet Impact, Ejections, Gun VFX, VFX) | D20: VFX — Particles | E20: Realistic muzzle flashes, bullet impacts and shell ejections. | F20: Collection ↗ | G20: Asset Store ↗ | H20: 49.99 | I20: No | J20: Lost the muzzle-flash shoot-out to Shots VFX URP (Round 2, R2.3). Impact effects are still usable. | L20: Docs ↗ | M20: Realistic Gun VFX Muzzle Flash Bullet Impact Ejections Gun VFX VFX v1.0 | N20: Yes | O20: Owned | Q20: Hivemind | R20: 1.0 | S20: 2026-03-09
B21: AST-018 | C21: Procedural Lightning - High Performance and Shocking Lightning | D21: VFX — Particles | E21: High-performance procedural lightning bolts, arcs and beams, with sounds. | F21: Collection ↗ | G21: Asset Store ↗ | H21: 20 | I21: No | J21: Adopted for MRM-57 (storm) and MRM-36 (Furman's bolt). | L21: Docs ↗ | M21: Procedural Lightning - High Performance and Shocking Lightning v3.0.3 | N21: Yes | O21: Owned | Q21: Digital Ruby (Jeff Johnson) | R21: 3.0.3 | S21: 2026-08-29
B22: AST-019 | C22: Cult Animations | D22: Animation — Clips & Mocap | E22: 25 motion-captured cult / ritual animations. | F22: Collection ↗ | G22: Asset Store ↗ | H22: 8 | I22: No | J22: Adopted for MRM-59 cult staging scenes. | M22: Cult Animations v1.0 | N22: Yes | O22: Owned | Q22: Gem Gaming Animations | R22: 1.0 | S22: 2024-05-31
B23: AST-020 | C23: Fly Particles + Sound Effects | D23: VFX — Particles | E23: Fly swarm particle systems with buzzing sounds. | F23: Collection ↗ | G23: Asset Store ↗ | H23: 4.99 | I23: No | J23: Adopted for MRM-60 ambience (corpses, rotting areas). | M23: Fly Particle System v1.0.1 | N23: Yes | O23: Owned | Q23: SpeedTutor | R23: 1.0 | S23: 2023-05-15
B24: AST-021 | C24: Artistic: Radial Blur | D24: Shaders & Post-Processing | E24: Artistic radial blur post effect (speed, focus, panic). | F24: Collection ↗ | G24: Asset Store ↗ | H24: 15 | I24: No | J24: Adopted for MRM-54 fear and MRM-53 low health — one shared channel. | M24: Artistic Radial Blur v2.1.2 (03 Sep 2025) | N24: No | O24: Owned | Q24: Fronkon Games | R24: 3.0.1 | S24: 2026-02-22
B25: AST-022 | C25: ANIMSET: 2 HANDED MELEE WEAPON | D25: Animation — Clips & Mocap | E25: Mocap animation set for two-handed melee weapons. | F25: Collection ↗ | G25: Asset Store ↗ | H25: 19.99 | I25: No | J25: Adopted for MRM-23 melee. Also included inside Ultimate Animation Collection. | M25: ANIMSET 2 HANDED MELEE WEAPON v1.5 | N25: No | O25: Owned | Q25: PROTOFACTOR, INC | R25: 1.642 | S25: 2026-07-06
B26: AST-023 | C26: Spice Up: Ghost Vision | D26: Shaders & Post-Processing | E26: 'Ghost vision' full-screen camera effect (Fronkon Spice Up). | F26: Collection ↗ | G26: Asset Store ↗ | H26: 15 | I26: No | J26: Adopted for MRM-55 — morphine effect. | M26: Spice Up Ghost Vision v2.1.0 | N26: No | O26: Owned | Q26: Fronkon Games | R26: 3.0.0 | S26: 2026-03-09
B27: AST-024 | C27: Spice Up: Stoned | D27: Shaders & Post-Processing | E27: 'Stoned' full-screen camera effect (Fronkon Spice Up). | F27: Collection ↗ | G27: Asset Store ↗ | H27: 15 | I27: No | J27: Adopted for MRM-55 — weed effect. | M27: Spice Up Stoned v1.2.0 | N27: No | O27: Owned | Q27: Fronkon Games | R27: 3.0.0 | S27: 2026-03-09
B28: AST-025 | C28: Spice Up: Rain | D28: Shaders & Post-Processing | E28: Raindrops-on-lens screen effect; can emulate blood or oil on the screen. | F28: Collection ↗ | G28: Asset Store ↗ | H28: 15 | I28: No | J28: Adopted for MRM-53 — blood on the lens. | M28: Spice Up Rain v1.2.0 | N28: No | O28: Owned | Q28: Fronkon Games | R28: 3.0.0 | S28: 2026-03-09
B29: AST-026 | C29: Knife_MocapAnimPack_1.1 | D29: Animation — Clips & Mocap | E29: Mocap knife combat animation pack. | F29: Collection ↗ | G29: Asset Store ↗ | H29: 45 | I29: No | J29: Adopted for MRM-35 knife-wielding enemy. | M29: Knife_MocapAnimPack v1.1 (21 Aug 2026) | N29: Yes | O29: Owned | Q29: RIB Studio | R29: 1.1 | S29: 2026-08-24
B30: AST-027 | C30: Spice Up: BodyCam | D30: Shaders & Post-Processing | E30: Police body-camera full-screen effect (fisheye, timestamp, noise). | F30: Collection ↗ | G30: Asset Store ↗ | H30: 15 | I30: No | J30: Adopted for MRM-49 — telescope aperture. | M30: Spice Up BodyCam v2.1.2 (22 Apr 2025) | N30: No | O30: Owned | Q30: Fronkon Games | R30: 3.0.1 | S30: 2026-06-21
B31: AST-028 | C31: Asset Cleaner PRO - Clean | Find References | D31: Editor Tools & Utilities | E31: Finds unused assets and tracks references across the project. | F31: Collection ↗ | G31: Asset Store ↗ | H31: 30 | I31: No | J31: Adopted for MRM-64. ⚠ Use find-references only — never bulk-delete. | M31: Asset Cleaner PRO - Clean Find References v1.51 | N31: Yes | O31: Owned | Q31: GameDev Tools | R31: 1.51 | S31: 2026-07-13
B32: AST-029 | C32: Sounds Good - Easy & Optimized Audio Manager | D32: Audio Tools | E32: Easy, pooled audio manager: sounds, music, playlists, dynamic music with one line of code. | F32: Collection ↗ | G32: Asset Store ↗ | H32: 15 | I32: No | J32: Adopted as the playback/pool backend for MRM-38 / 39 / 65 — not migrated yet. | K32: [Claude] 2026-10-11: v2.3.0 downloaded (was 2.2.2); NOT yet synced into the project. | L32: Docs ↗ | M32: Sounds Good - Easy Optimized Audio Manager v2.3.0 | N32: Yes | O32: Owned | Q32: Melenitas Dev | R32: 2.3.0 | S32: 2026-10-05
B33: AST-030 | C33: Ambient Sounds - Interactive Soundscapes for Unity 6 | D33: Audio Tools | E33: Interactive, zone-based soundscape system (Procedural Worlds). | F33: Collection ↗ | G33: Asset Store ↗ | H33: 49 | I33: No | J33: Rejected — MRM-38's own sound-layer system already covers zones. | L33: Docs ↗ | M33: Ambient Sounds - Interactive Soundscapes for Unity 6 v1.2.19 | N33: Yes | O33: Owned | Q33: Procedural Worlds Inc | R33: 1.2.19 | S33: 2026-06-30
B34: AST-031 | C34: Low Poly Plant Collections | D34: Vegetation & Nature | E34: 50+ stylized hand-painted low-poly plants with LODs. | F34: Collection ↗ | G34: Asset Store ↗ | H34: 16.99 | I34: Yes | J34: MRM-70 island vegetation (Art/Environment/Vegetation/LowPolyPlants). | M34: Low Poly Plant Collections v2.1 (11 Jul 2023) | N34: Yes | O34: Owned | Q34: Gamester | R34: 2.1 | S34: 2023-07-11
B35: AST-032 | C35: Volumetric Light Beam | D35: Shaders & Post-Processing | E35: Efficient volumetric light-beam cones for spotlights. | F35: Collection ↗ | G35: Asset Store ↗ | H35: 44.9 | I35: No | J35: Parked for MRM-44 flashlight beams — test HAZE alone first. | L35: Docs ↗ | M35: Volumetric Light Beam v2.2.8 | N35: No | O35: Owned | Q35: Tech Salad | R35: 2.2.9 | S35: 2026-09-04
B36: AST-033 | C36: Flying Birds VFX | D36: VFX — Particles | E36: 3D birds that fly in loops around a point, alternating glide and flap. | F36: Collection ↗ | G36: Realtime VFX Store ↗ | H36: 15 | I36: Yes | J36: Installed with vendor code — ambient bird flocks over the island (MRM-59). | M36: Flying Birds VFX v1.0 | N36: Yes | O36: Owned | Q36: Realtime VFX Store | R36: 1.0
B37: AST-034 | C37: Insect VFX [HDRP, URP] | D37: VFX — Particles | E37: VFX Graph insect swarms: cockroaches, moths, flies. | F37: Collection ↗ | G37: Asset Store ↗ | H37: 14.99 | I37: No | J37: Adopted for MRM-60 / MRM-61 ambience. | L37: Docs ↗ | M37: Insect VFX HDRP URP v3.0.0 | N37: Yes | O37: Owned | Q37: Paulina VFX | R37: 3.0.0 | S37: 2026-06-15
B38: AST-035 | C38: HQ Realistic explosions | D38: VFX — Particles | E38: 26 realistic explosions with 4 custom shaders. | F38: Collection ↗ | G38: Asset Store ↗ | H38: 15 | I38: No | J38: Adopted for MRM-57. | M38: HQ Realistic explosions v2.1.0 (10 Nov 2024) | N38: Yes | O38: Owned | Q38: Hovl Studio | R38: 2.1.0 | S38: 2024-11-09
B39: AST-036 | C39: Bullet Impact VFX and Bullet Hole Decals With Sounds | D39: VFX — Particles | E39: Bullet impact particles, bullet-hole decals and impact sounds per surface. | F39: Collection ↗ | G39: Asset Store ↗ | H39: 39.99 | I39: No | J39: Adopted for MRM-22 / MRM-24 impacts + decals (shares a surface lookup with MRM-39). | M39: Bullet Impact VFX and Bullet Hole Decals With Sounds v1.9 (22 Dec 2025) | N39: Yes | O39: Owned | Q39: Medartimus | R39: V.1.9 | S39: 2025-12-22
B40: AST-037 | C40: Shots VFX - URP | D40: VFX — Particles | E40: Stylized gunshot / muzzle flash VFX for URP. | F40: Collection ↗ | G40: Asset Store ↗ | H40: 34.97 | I40: No | J40: Won the muzzle-flash call (R2.3) for MRM-22 / 24 / 52 — migration still pending. | M40: Shots VFX - URP v1.0.21 | N40: Yes | O40: Owned | Q40: Vefects | R40: 1.0.21 | S40: 2026-01-07
...

Sheet Legend
B2: How to read the index
B3: ID (AST-###) | C3: Permanent identifier. Numbers were assigned once, in this file's order; they never change if you sort, filter or add rows. New assets get the next free number.
B4: Yellow row | C4: Owned or already used in Mr. Moonlight, but missing from your original list.
B5: Price in green | C5: The asset has a collection URL.
B6: Price in red | C6: No collection URL — the store/source is the only place to get it.
B7: Price | C7: Full (non-sale) price in USD. 'Free' = $0. itch.io 'Pay what you want' and unreadable pages are written as text.
B8: in Mr Moonlight? = Yes (green) | C8: Actually installed or used in the Mr. Moonlight project today (checked against the project folders and docs), not just planned. The ticket is at the start of the purpose column.
B9: up to date? = No (orange) | C9: The Asset Store has a newer version than your downloaded file. 'Unknown' = the version isn't recorded. Store versions read on 2026-09-16.
B10: status / priority | C10: Owned rows have no priority. The wishlist is sorted by priority; #1 is the first thing to get.
B12: Priority tiers
B13: P1 · Get first — Mr. Moonlight demo | C13: 13 assets · ~$133.41 at full price · Direct value for the demo now: enemy AI/senses, horror enemies and animations, gore, flashlight, UI sound, free packs.
B14: P2 · Mr. Moonlight — October / later | C14: 5 assets · ~$138.95 at full price · Useful for Mr. Moonlight but not urgent: cutscenes, optimization, destructible trees, swimming, boats.
B15: P3 · General toolkit — other projects | C15: 15 assets · ~$817.96 at full price · Strong general tools for future projects: procedural generation, anti-cheat, networking, IK/physics.
B16: P4 · Niche templates & packs | C16: 4 assets · ~$218.97 at full price · Genre templates and niche packs, kept for reference.
B17: P5 · Personal library — anime / gooner | C17: 11 assets · ~$660.00 at full price · Personal library, not for Mr. Moonlight.
B19: Categories
B20: AI & Behavior | C20: 8 assets
B21: Animation & Rigging Tools | C21: 14 assets
B22: Animation — Clips & Mocap | C22: 25 assets
B23: Audio Tools | C23: 2 assets
B24: Audio — Music | C24: 4 assets
B25: Audio — SFX & Ambience | C25: 13 assets
B26: Blender Add-ons | C26: 2 assets
B27: Characters — Animals | C27: 5 assets
B28: Characters — Anime | C28: 5 assets
B29: Characters — Gooner | C29: 24 assets
B30: Characters — Horror & Creatures | C30: 11 assets
B31: Characters — Humans & Stylized | C31: 9 assets
... B51: Water | C51: 8 assets
B53: Changes made while building this file
B54: Duplicates merged | C54: BloodOcean, Aoi Character Pack, Magica Cloth 2, Advanced Zombie AI, Weeper Horror Ghost Pack, Classic Female Ghost and Anime Girl Characters – Bikini were each listed twice. Merged into one row, notes combined.
B55: Wrong links fixed | C55: URP Wet Shaders pointed to Log Cabin · Survival Horror Game Music Pack pointed to Screenspace VFX · CombatGirls Pistol's collection link pointed to the Dual Pistol pack.
B56: Moved to owned | C56: PSX Flashlight / Lantern Pack 6 — its lamp is already in the project (Art/Props/Lamp).
B57: Not found on the Asset Store | C57: Alice Style Character, Anime Style Girl: Haruka, Anime Girl Characters – Bikini, Monster Sounds Pack, Guns Sound Essentials — probably delisted; only the collection links work.
B58: 2026-09-19 update | C58: 14 newly downloaded files. 11 were wishlist rows (AST-118 to 126, 144, 147): moved into the 'OWNED (FROM WISHLIST)' section, original ranks kept in the priority column. 3 were on no list and got new IDs: AST-264 SensorToolkit 2, AST-265 Emerald AI 2026, AST-266 Advanced Cable Creator (yellow rows). The wishlist tier totals above now count only what is still un-owned. This file moved from Desktop\assets to Documents\Asset Collection\03_documentation.
B59: 2026-09-19 update (2nd) | C59: 13 more downloaded files, every one already a wishlist row (AST-127, 128, 129, 131, 132, 134, 135, 137, 142, 143, 156, 157, 232): moved into the 'OWNED (FROM WISHLIST)' section, original ranks kept in the priority column. No new IDs. AST-143 Cineaster is marked 'No' for up to date (file v1.0.2, store 1.0.3). The tier totals above now count only what is still un-owned.
B60: 2026-09-21 update | C60: 13 more downloaded files, every one already a wishlist row (AST-130, 133, 139, 150, 151, 155, 162, 163, 164, 165, 166, 171, 173): moved into the 'OWNED (FROM WISHLIST)' section, original ranks kept in the priority column. No new IDs. Not installed in any project. Two are behind the store: AST-165 Crest Water 5 - Whirlpool (file 1.0.3, store 1.1.2) and AST-173 DunGen (file 2.18.14, store 2.19.13). AST-151 Monster Sounds Pack has no store version, so 'Unknown'. Tier totals recomputed.
B61: 2026-09-21 update (2nd) | C61: AST-116 Technie Collider Creator 2 moved from 'OWNED (FROM WISHLIST)' to 'OWNED — downloaded assets' and marked in Mr. Moonlight = Yes (installed at Assets/Technie/PhysicsCreator, used for MRM-84). AST-147 Asset Optimizer Pro and AST-164 Ether Skyboxes staged in the Playground project (noted in their notes column); AST-054 Skybox Blender was already there.
B62: 2026-09-25 update | C62: 9 more downloaded files. 7 were wishlist rows (AST-167, 168, 169, 170, 184, 205, 206): moved into the 'OWNED (FROM WISHLIST)' section, original ranks kept in the priority column. 2 were on no list and got new IDs (AST-267 Cutscene Engine, AST-268 Procedural Generation Grid (Beta)), yellow rows. Tier totals and category counts recomputed.
B63: 2026-09-29 update | C63: 20 more downloaded files. 9 were wishlist rows (AST-175, 176, 177, 183, 187, 189, 190, 194, 195): moved into the 'OWNED (FROM WISHLIST)' section, original ranks kept in the priority column. 11 were on no list and got new IDs AST-269 to AST-279 (Advanced Dissolve, Medieval Wells Props, Draw Debug Tools, Dynamic Water Physics 2, Essential Footsteps SFX, Exporter for Unreal to/for Unity, Magic Time, Sci-Fi Game Sound Effects, SmartBuilder, Survival Essentials Pack, Ultimate Sound FX Bundle), yellow rows. Behind the store: AST-175, 176, 177, 183, 190, 195. AST-279 has no store page (publisher, price and version unknown). Tier totals and category counts recomputed.
...
